Workbook

Sheet Основные данные
A1: Дата | B1: Час | C1: Рабочий день | D1: Электропотребление
A2: 43466 | B2: 1 | C2: 0 | D2: 215.191
A3: 43466 | B3: 2 | C3: 0 | D3: 202.239
A4: 43466 | B4: 3 | C4: 0 | D4: 188.462
A5: 43466 | B5: 4 | C5: 0 | D5: 179.276
A6: 43466 | B6: 5 | C6: 0 | D6: 173.035
A7: 43466 | B7: 6 | C7: 0 | D7: 171.083
A8: 43466 | B8: 7 | C8: 0 | D8: 170.907
A9: 43466 | B9: 8 | C9: 0 | D9: 168.163
A10: 43466 | B10: 9 | C10: 0 | D10: 169.645
A11: 43466 | B11: 10 | C11: 0 | D11: 176.945
A12: 43466 | B12: 11 | C12: 0 | D12: 185.645
A13: 43466 | B13: 12 | C13: 0 | D13: 191.851
... A30721: 44745 | B30721: 24 | C30721: 0 | D30721: 135.9746
A30722: =A30698+1 -> 44746 | B30722: 1 | C30722: 1 | D30722: 129.463
A30723: =A30699+1 -> 44746 | B30723: 2 | C30723: 1 | D30723: 120.462
A30724: =A30700+1 -> 44746 | B30724: 3 | C30724: 1 | D30724: 115.658
A30725: =A30701+1 -> 44746 | B30725: 4 | C30725: 1 | D30725: 113.123
A30726: =A30702+1 -> 44746 | B30726: 5 | C30726: 1 | D30726: 109.538
A30727: =A30703+1 -> 44746 | B30727: 6 | C30727: 1 | D30727: 106.688
A30728: =A30704+1 -> 44746 | B30728: 7 | C30728: 1 | D30728: 116.017
A30729: =A30705+1 -> 44746 | B30729: 8 | C30729: 1 | D30729: 133.585
A30730: =A30706+1 -> 44746 | B30730: 9 | C30730: 1 | D30730: 154.137
A30731: =A30707+1 -> 44746 | B30731: 10 | C30731: 1 | D30731: 174.467
A30732: =A30708+1 -> 44746 | B30732: 11 | C30732: 1 | D30732: 183.551
A30733: =A30709+1 -> 44746 | B30733: 12 | C30733: 1 | D30733: 182.959
... A30817: =A30793+1 -> 44749 | B30817: 24 | C30817: 1 | D30817: 150.38613

Sheet Лист2
A1: Дата | B1: Час | C1: Электропотребление | D1: Рабочий день
A2: ='Основные данные'!A30794+1 -> 44750 | B2: 1 | D2: 1
A3: ='Основные данные'!A30795+1 -> 44750 | B3: 2 | D3: 1
A4: ='Основные данные'!A30796+1 -> 44750 | B4: 3 | D4: 1
A5: ='Основные данные'!A30797+1 -> 44750 | B5: 4 | D5: 1
A6: ='Основные данные'!A30798+1 -> 44750 | B6: 5 | D6: 1
A7: ='Основные данные'!A30799+1 -> 44750 | B7: 6 | D7: 1
A8: ='Основные данные'!A30800+1 -> 44750 | B8: 7 | D8: 1
A9: ='Основные данные'!A30801+1 -> 44750 | B9: 8 | D9: 1
A10: ='Основные данные'!A30802+1 -> 44750 | B10: 9 | D10: 1
A11: ='Основные данные'!A30803+1 -> 44750 | B11: 10 | D11: 1
A12: ='Основные данные'!A30804+1 -> 44750 | B12: 11 | D12: 1
A13: ='Основные данные'!A30805+1 -> 44750 | B13: 12 | D13: 1
... A25: ='Основные данные'!A30817+1 -> 44750 | B25: 24 | D25: 1
A26: =A2+1 -> 44751 | B26: 1 | D26: 0
A27: =A3+1 -> 44751 | B27: 2 | D27: 0
A28: =A4+1 -> 44751 | B28: 3 | D28: 0
A29: =A5+1 -> 44751 | B29: 4 | D29: 0
A30: =A6+1 -> 44751 | B30: 5 | D30: 0
A31: =A7+1 -> 44751 | B31: 6 | D31: 0
A32: =A8+1 -> 44751 | B32: 7 | D32: 0
A33: =A9+1 -> 44751 | B33: 8 | D33: 0
A34: =A10+1 -> 44751 | B34: 9 | D34: 0
A35: =A11+1 -> 44751 | B35: 10 | D35: 0
A36: =A12+1 -> 44751 | B36: 11 | D36: 0
A37: =A13+1 -> 44751 | B37: 12 | D37: 0
... A577: =A553+1 -> 44773 | B577: 24 | D577: 0
A578: 44774 | B578: 1 | D578: 1
A579: 44774 | B579: 2 | D579: 1
A580: 44774 | B580: 3 | D580: 1
A581: 44774 | B581: 4 | D581: 1
A582: 44774 | B582: 5 | D582: 1
A583: 44774 | B583: 6 | D583: 1
A584: 44774 | B584: 7 | D584: 1
A585: 44774 | B585: 8 | D585: 1
A586: 44774 | B586: 9 | D586: 1
A587: 44774 | B587: 10 | D587: 1
A588: 44774 | B588: 11 | D588: 1
A589: 44774 | B589: 12 | D589: 1
... A601: 44774 | B601: 24 | D601: 1
...
